<?xml version="1.0" encoding="utf-8"?>
<!-- This URDF was automatically created by SolidWorks to URDF Exporter! Originally created by Stephen Brawner (brawner@gmail.com) 
     Commit Version: 1.6.0-4-g7f85cfe  Build Version: 1.6.7995.38578
     For more information, please see http://wiki.ros.org/sw_urdf_exporter -->
<robot
  name="engineer_arm_urdf">
  <mujoco>
      <compiler 
      meshdir="./meshes/" 
      balanceinertia="true" 
      discardvisual="false" />
  </mujoco>
  <link name="dummy_link">
  </link>
  <link
    name="base_link">
    <inertial>
      <origin
        xyz="-0.00181394454555794 0.0247175436624614 8.39396911295996E-05"
        rpy="0 0 0" />
      <mass
        value="0.879212197102581" />
      <inertia
        ixx="0.0015848"
        ixy="-1.97913779588492E-07"
        ixz="-1.73954370934509E-06"
        iyy="0.0014979"
        iyz="-7.70158458895671E-09"
        izz="0.0016803" />
    </inertial>
    <visual>
      <origin
        xyz="0 0 0"
        rpy="0 0 0" />
      <geometry>
        <mesh
          filename="./meshes/base_link.STL" />
      </geometry>
      <material
        name="">
        <color
          rgba="0.792156862745098 0.819607843137255 0.933333333333333 1" />
      </material>
    </visual>
    <collision>
      <origin
        xyz="0 0 0"
        rpy="0 0 0" />
      <geometry>
        <mesh
          filename="./meshes/base_link.STL" />
      </geometry>
    </collision>
  </link>
  <joint name="dummy" type="fixed">
    <origin xyz="0 0 0" rpy="0 0 0" />
    <parent link="dummy_link" />
    <child link="base_link" />
  </joint>
  <link
    name="link1">
    <inertial>
      <origin
        xyz="0.056000854600132 -6.1834998132837E-05 -0.00164063969604794"
        rpy="0 0 0" />
      <mass
        value="1.27100950864182" />
      <inertia
        ixx="0.0020770"
        ixy="0.0000059"
        ixz="-0.0002232"
        iyy="0.0063972"
        iyz="-0.0000022"
        izz="0.0069407" />
    </inertial>
    <visual>
      <origin
        xyz="0 0 0"
        rpy="0 0 0" />
      <geometry>
        <mesh
          filename="./meshes/link1.STL" />
      </geometry>
      <material
        name="">
        <color
          rgba="0.898039215686275 0.917647058823529 0.929411764705882 1" />
      </material>
    </visual>
    <collision>
      <origin
        xyz="0 0 0"
        rpy="0 0 0" />
      <geometry>
        <mesh
          filename="./meshes/link1.STL" />
      </geometry>
    </collision>
  </link>
  <joint
    name="joint1"
    type="continuous">
    <origin
      xyz="0 0.061 0"
      rpy="0 0 1.5707963267949" />
    <parent
      link="base_link" />
    <child
      link="link1" />
    <axis
      xyz="-1 0 0" />
    <limit
      lower="0"
      upper="0"
      effort="0"
      velocity="0" />
  </joint>
  <link
    name="link2">
    <inertial>
      <origin
        xyz="-0.015433671666134 2.6144608808315E-06 0.189043916479842"
        rpy="0 0 0" />
      <mass
        value="1.06003207402486" />
      <inertia
        ixx="0.0626877"
        ixy="0.0"
        ixz="-0.0031933"
        iyy="0.0634036"
        iyz="0.0000009"
        izz="0.0015546" />
    </inertial>
    <visual>
      <origin
        xyz="0 0 0"
        rpy="0 0 0" />
      <geometry>
        <mesh
          filename="./meshes/link2.STL" />
      </geometry>
      <material
        name="">
        <color
          rgba="0.898039215686275 0.917647058823529 0.929411764705882 1" />
      </material>
    </visual>
    <collision>
      <origin
        xyz="0 0 0"
        rpy="0 0 0" />
      <geometry>
        <mesh
          filename="./meshes/link2.STL" />
      </geometry>
    </collision>
  </link>
  <joint
    name="joint2"
    type="continuous">
    <origin
      xyz="0.0649999999999999 0 0.0145"
      rpy="1.5707963267949 -1.5707963267949 0" />
    <parent
      link="link1" />
    <child
      link="link2" />
    <axis
      xyz="-1 0 0" />
    <limit
      lower="0"
      upper="0"
      effort="0"
      velocity="0" />
  </joint>
  <link
    name="link3">
    <inertial>
      <origin
        xyz="0.0328573437408591 0.000118784068100286 -0.187894192781923"
        rpy="0 0 0" />
      <mass
        value="0.513825207873787" />
      <inertia
        ixx="0.0250230"
        ixy="0.0000021"
        ixz="-0.0037718"
        iyy="0.0256084"
        iyz="-0.0000156"
        izz="0.0008140" />
    </inertial>
    <visual>
      <origin
        xyz="0 0 0"
        rpy="0 0 0" />
      <geometry>
        <mesh
          filename="./meshes/link3.STL" />
      </geometry>
      <material
        name="">
        <color
          rgba="0.898039215686275 0.917647058823529 0.929411764705882 1" />
      </material>
    </visual>
    <collision>
      <origin
        xyz="0 0 0"
        rpy="0 0 0" />
      <geometry>
        <mesh
          filename="./meshes/link3.STL" />
      </geometry>
    </collision>
  </link>
  <joint
    name="joint3"
    type="continuous">
    <origin
      xyz="0.00930000000000006 0 0.325"
      rpy="-3.14159265358979 0 0" />
    <parent
      link="link2" />
    <child
      link="link3" />
    <axis
      xyz="-1 0 0" />
    <limit
      lower="0"
      upper="0"
      effort="0"
      velocity="0" />
  </joint>
  <link
    name="link4">
    <inertial>
      <origin
        xyz="-0.0321935302713612 -0.00380223583040232 -0.000173813491123331"
        rpy="0 0 0" />
      <mass
        value="0.350378887571842" />
      <inertia
        ixx="0.0001795"
        ixy="0.0000452"
        ixz="0.0000021"
        iyy="0.0005659"
        iyz="0.0000005"
        izz="0.0005561" />
    </inertial>
    <visual>
      <origin
        xyz="0 0 0"
        rpy="0 0 0" />
      <geometry>
        <mesh
          filename="./meshes/link4.STL" />
      </geometry>
      <material
        name="">
        <color
          rgba="0.898039215686275 0.917647058823529 0.929411764705882 1" />
      </material>
    </visual>
    <collision>
      <origin
        xyz="0 0 0"
        rpy="0 0 0" />
      <geometry>
        <mesh
          filename="./meshes/link4.STL" />
      </geometry>
    </collision>
  </link>
  <joint
    name="joint4"
    type="continuous">
    <origin
      xyz="0.0112000000000001 0 -0.240000000000001"
      rpy="0 0 0" />
    <parent
      link="link3" />
    <child
      link="link4" />
    <axis
      xyz="-1 0 0" />
    <limit
      lower="0"
      upper="0"
      effort="0"
      velocity="0" />
  </joint>
  <link
    name="link5">
    <inertial>
      <origin
        xyz="0.0331935302713713 -0.000173813491137185 -0.00380223583039918"
        rpy="0 0 0" />
      <mass
        value="0.350378887571855" />
      <inertia
        ixx="0.0001795"
        ixy="-0.0000021"
        ixz="-0.0000466"
        iyy="0.0005791"
        iyz="0.0000005"
        izz="0.0005889" />
    </inertial>
    <visual>
      <origin
        xyz="0 0 0"
        rpy="0 0 0" />
      <geometry>
        <mesh
          filename="./meshes/link5.STL" />
      </geometry>
      <material
        name="">
        <color
          rgba="0.898039215686275 0.917647058823529 0.929411764705882 1" />
      </material>
    </visual>
    <collision>
      <origin
        xyz="0 0 0"
        rpy="0 0 0" />
      <geometry>
        <mesh
          filename="./meshes/link5.STL" />
      </geometry>
    </collision>
  </link>
  <joint
    name="joint5"
    type="continuous">
    <origin
      xyz="-0.0349999999999875 -0.03 0"
      rpy="0 0 -1.5707963267949" />
    <parent
      link="link4" />
    <child
      link="link5" />
    <axis
      xyz="-1 0 0" />
    <limit
      lower="0"
      upper="0"
      effort="0"
      velocity="0" />
  </joint>
  <link
    name="link6">
    <inertial>
      <origin
        xyz="-0.0203388381591695 -5.59495728582118E-05 -0.000683683023469682"
        rpy="0 0 0" />
      <mass
        value="0.183107517761054" />
      <inertia
        ixx="0.0000751"
        ixy="1.56460728162457E-08"
        ixz="1.91248815451878E-07"
        iyy="0.0001502"
        iyz="2.50770687569931E-07"
        izz="0.0001531" />
    </inertial>
    <visual>
      <origin
        xyz="0 0 0"
        rpy="0 0 0" />
      <geometry>
        <mesh
          filename="./meshes/link6.STL" />
      </geometry>
      <material
        name="">
        <color
          rgba="0.898039215686275 0.917647058823529 0.929411764705882 1" />
      </material>
    </visual>
    <collision>
      <origin
        xyz="0 0 0"
        rpy="0 0 0" />
      <geometry>
        <mesh
          filename="./meshes/link6.STL" />
      </geometry>
    </collision>
  </link>
  <joint
    name="joint6"
    type="continuous">
    <origin
      xyz="0.0359999999999991 0 -0.0830000000000004"
      rpy="1.5707963267949 1.5707963267949 0" />
    <parent
      link="link5" />
    <child
      link="link6" />
    <axis
      xyz="1 0 0" />
    <limit
      lower="0"
      upper="0"
      effort="0"
      velocity="0" />
  </joint>
</robot>